2024-08-31 09:09:29,022 - ERROR - Exception on /withdraw/gAAAAABm0t3C6nDrAmt3golUrrYxoq2RmBVbxBQvYYK9hkcwpiprvTVCHanpeVOnxDmaB_u0xD4kJp5tMbuN3yAO3duZxvnolw== [POST]
Traceback (most recent call last):
  File "/usr/local/lib/python3.8/site-packages/flask/app.py", line 1473, in wsgi_app
    response = self.full_dispatch_request()
  File "/usr/local/lib/python3.8/site-packages/flask/app.py", line 882, in full_dispatch_request
    rv = self.handle_user_exception(e)
  File "/usr/local/lib/python3.8/site-packages/flask/app.py", line 880, in full_dispatch_request
    rv = self.dispatch_request()
  File "/usr/local/lib/python3.8/site-packages/flask/app.py", line 865, in dispatch_request
    return self.ensure_sync(self.view_functions[rule.endpoint])(**view_args)  # type: ignore[no-any-return]
  File "/app/app/withdraw.py", line 69, in withdraw
    return render_template('withdraw.html', user=user, account_number=account_number)
  File "/usr/local/lib/python3.8/site-packages/flask/templating.py", line 150, in render_template
    return _render(app, template, context)
  File "/usr/local/lib/python3.8/site-packages/flask/templating.py", line 131, in _render
    rv = template.render(context)
  File "/usr/local/lib/python3.8/site-packages/jinja2/environment.py", line 1304, in render
    self.environment.handle_exception()
  File "/usr/local/lib/python3.8/site-packages/jinja2/environment.py", line 939, in handle_exception
    raise rewrite_traceback_stack(source=source)
  File "/app/app/templates/withdraw.html", line 16, in top-level template code
    <p>Current Balance: {{ account.balance }}</p>
  File "/usr/local/lib/python3.8/site-packages/jinja2/environment.py", line 487, in getattr
    return getattr(obj, attribute)
jinja2.exceptions.UndefinedError: 'account' is undefined
2024-08-31 09:14:52,296 - ERROR - Exception on /emi_payment/1821014504 [GET]
Traceback (most recent call last):
  File "/usr/local/lib/python3.8/site-packages/flask/app.py", line 1473, in wsgi_app
    response = self.full_dispatch_request()
  File "/usr/local/lib/python3.8/site-packages/flask/app.py", line 882, in full_dispatch_request
    rv = self.handle_user_exception(e)
  File "/usr/local/lib/python3.8/site-packages/flask/app.py", line 880, in full_dispatch_request
    rv = self.dispatch_request()
  File "/usr/local/lib/python3.8/site-packages/flask/app.py", line 865, in dispatch_request
    return self.ensure_sync(self.view_functions[rule.endpoint])(**view_args)  # type: ignore[no-any-return]
TypeError: emi_payment() got an unexpected keyword argument 'encrypted_account_number'
2024-08-31 09:14:56,979 - ERROR - Exception on /loan_account_statement/1821014504 [GET]
Traceback (most recent call last):
  File "/usr/local/lib/python3.8/site-packages/flask/app.py", line 1473, in wsgi_app
    response = self.full_dispatch_request()
  File "/usr/local/lib/python3.8/site-packages/flask/app.py", line 882, in full_dispatch_request
    rv = self.handle_user_exception(e)
  File "/usr/local/lib/python3.8/site-packages/flask/app.py", line 880, in full_dispatch_request
    rv = self.dispatch_request()
  File "/usr/local/lib/python3.8/site-packages/flask/app.py", line 865, in dispatch_request
    return self.ensure_sync(self.view_functions[rule.endpoint])(**view_args)  # type: ignore[no-any-return]
  File "/app/app/loan_account_statement.py", line 10, in loan_account_statement
    account_number = decrypt_account_number(encrypted_account_number)
NameError: name 'decrypt_account_number' is not defined
2024-08-31 09:37:07,928 - ERROR - Exception on /search [GET]
Traceback (most recent call last):
  File "/usr/local/lib/python3.8/site-packages/flask/app.py", line 1473, in wsgi_app
    response = self.full_dispatch_request()
  File "/usr/local/lib/python3.8/site-packages/flask/app.py", line 882, in full_dispatch_request
    rv = self.handle_user_exception(e)
  File "/usr/local/lib/python3.8/site-packages/flask/app.py", line 880, in full_dispatch_request
    rv = self.dispatch_request()
  File "/usr/local/lib/python3.8/site-packages/flask/app.py", line 865, in dispatch_request
    return self.ensure_sync(self.view_functions[rule.endpoint])(**view_args)  # type: ignore[no-any-return]
  File "/app/app/search.py", line 25, in search
    return render_template('search.html', users=users, account=account)
  File "/usr/local/lib/python3.8/site-packages/flask/templating.py", line 150, in render_template
    return _render(app, template, context)
  File "/usr/local/lib/python3.8/site-packages/flask/templating.py", line 131, in _render
    rv = template.render(context)
  File "/usr/local/lib/python3.8/site-packages/jinja2/environment.py", line 1304, in render
    self.environment.handle_exception()
  File "/usr/local/lib/python3.8/site-packages/jinja2/environment.py", line 939, in handle_exception
    raise rewrite_traceback_stack(source=source)
  File "/app/app/templates/search.html", line 37, in top-level template code
    <a href="{{ url_for('deposit', account_number=account.account_number) }}" class="button">Deposit</a>
  File "/usr/local/lib/python3.8/site-packages/flask/app.py", line 1084, in url_for
    return self.handle_url_build_error(error, endpoint, values)
  File "/usr/local/lib/python3.8/site-packages/flask/app.py", line 1073, in url_for
    rv = url_adapter.build(  # type: ignore[union-attr]
  File "/usr/local/lib/python3.8/site-packages/werkzeug/routing/map.py", line 924, in build
    raise BuildError(endpoint, values, method, self)
werkzeug.routing.exceptions.BuildError: Could not build url for endpoint 'deposit' with values ['account_number']. Did you forget to specify values ['encrypted_account_number']?
2024-08-31 09:39:06,144 - ERROR - Exception on /all_accounts [GET]
Traceback (most recent call last):
  File "/usr/local/lib/python3.8/site-packages/flask/app.py", line 1473, in wsgi_app
    response = self.full_dispatch_request()
  File "/usr/local/lib/python3.8/site-packages/flask/app.py", line 882, in full_dispatch_request
    rv = self.handle_user_exception(e)
  File "/usr/local/lib/python3.8/site-packages/flask/app.py", line 880, in full_dispatch_request
    rv = self.dispatch_request()
  File "/usr/local/lib/python3.8/site-packages/flask/app.py", line 865, in dispatch_request
    return self.ensure_sync(self.view_functions[rule.endpoint])(**view_args)  # type: ignore[no-any-return]
  File "/app/app/views.py", line 40, in decorated_function
    return f(*args, **kwargs)
  File "/app/app/views.py", line 110, in all_accounts
    return render_template('all_accounts.html', accounts=accounts, encrypt=encrypt, decrypt=decrypt)
  File "/usr/local/lib/python3.8/site-packages/flask/templating.py", line 150, in render_template
    return _render(app, template, context)
  File "/usr/local/lib/python3.8/site-packages/flask/templating.py", line 131, in _render
    rv = template.render(context)
  File "/usr/local/lib/python3.8/site-packages/jinja2/environment.py", line 1304, in render
    self.environment.handle_exception()
  File "/usr/local/lib/python3.8/site-packages/jinja2/environment.py", line 939, in handle_exception
    raise rewrite_traceback_stack(source=source)
  File "/app/app/templates/all_accounts.html", line 35, in top-level template code
    <a href="{{ url_for('statement.account_statement', encrypted_account_number=encrypt(account.account_number)) }}" class="button">View Statement</a>
  File "/usr/local/lib/python3.8/site-packages/flask/app.py", line 1084, in url_for
    return self.handle_url_build_error(error, endpoint, values)
  File "/usr/local/lib/python3.8/site-packages/flask/app.py", line 1073, in url_for
    rv = url_adapter.build(  # type: ignore[union-attr]
  File "/usr/local/lib/python3.8/site-packages/werkzeug/routing/map.py", line 924, in build
    raise BuildError(endpoint, values, method, self)
werkzeug.routing.exceptions.BuildError: Could not build url for endpoint 'statement.account_statement' with values ['encrypted_account_number']. Did you forget to specify values ['account_number']?
