2024-08-31 08:16:05,236 - ERROR - Exception on /view_user_details/gAAAAABm0tFDOCPdDfNmXynZAWoFEz6-UzYXBqLezKoWCEPekZw9U9-4Bd23OH5th-L9OZ-VTZcxhQFHUZZeuCu9oQfgHf4j_g== [GET]
Traceback (most recent call last):
  File "/usr/local/lib/python3.8/site-packages/flask/app.py", line 1473, in wsgi_app
    response = self.full_dispatch_request()
  File "/usr/local/lib/python3.8/site-packages/flask/app.py", line 882, in full_dispatch_request
    rv = self.handle_user_exception(e)
  File "/usr/local/lib/python3.8/site-packages/flask/app.py", line 880, in full_dispatch_request
    rv = self.dispatch_request()
  File "/usr/local/lib/python3.8/site-packages/flask/app.py", line 865, in dispatch_request
    return self.ensure_sync(self.view_functions[rule.endpoint])(**view_args)  # type: ignore[no-any-return]
  File "/app/app/views.py", line 40, in decorated_function
    return f(*args, **kwargs)
  File "/app/app/views.py", line 142, in view_user_details
    return render_template('view_user_details.html', user=user, account=account)
  File "/usr/local/lib/python3.8/site-packages/flask/templating.py", line 150, in render_template
    return _render(app, template, context)
  File "/usr/local/lib/python3.8/site-packages/flask/templating.py", line 131, in _render
    rv = template.render(context)
  File "/usr/local/lib/python3.8/site-packages/jinja2/environment.py", line 1304, in render
    self.environment.handle_exception()
  File "/usr/local/lib/python3.8/site-packages/jinja2/environment.py", line 939, in handle_exception
    raise rewrite_traceback_stack(source=source)
  File "/app/app/templates/view_user_details.html", line 98, in top-level template code
    <a href="{{ url_for('withdraw', encrypted_account_number=encypt(user.account_number)) }}" class="button"><i class="fas fa-money-bill-wave"></i> Withdraw</a>
  File "/usr/local/lib/python3.8/site-packages/jinja2/utils.py", line 83, in from_obj
    if hasattr(obj, "jinja_pass_arg"):
jinja2.exceptions.UndefinedError: 'encypt' is undefined
2024-08-31 08:18:50,600 - ERROR - Exception on /view_user_details/gAAAAABm0tHo5C-hPVt9C76UVsaYGVRK_csunGK-IzWgRq-0W0TA02vkmzaNxBBLP-3zx5ZvxRy0ugiFyMVmiQah1v3c3qzxeQ== [GET]
Traceback (most recent call last):
  File "/usr/local/lib/python3.8/site-packages/flask/app.py", line 1473, in wsgi_app
    response = self.full_dispatch_request()
  File "/usr/local/lib/python3.8/site-packages/flask/app.py", line 882, in full_dispatch_request
    rv = self.handle_user_exception(e)
  File "/usr/local/lib/python3.8/site-packages/flask/app.py", line 880, in full_dispatch_request
    rv = self.dispatch_request()
  File "/usr/local/lib/python3.8/site-packages/flask/app.py", line 865, in dispatch_request
    return self.ensure_sync(self.view_functions[rule.endpoint])(**view_args)  # type: ignore[no-any-return]
  File "/app/app/views.py", line 40, in decorated_function
    return f(*args, **kwargs)
  File "/app/app/views.py", line 142, in view_user_details
    return render_template('view_user_details.html', user=user, account=account)
  File "/usr/local/lib/python3.8/site-packages/flask/templating.py", line 150, in render_template
    return _render(app, template, context)
  File "/usr/local/lib/python3.8/site-packages/flask/templating.py", line 131, in _render
    rv = template.render(context)
  File "/usr/local/lib/python3.8/site-packages/jinja2/environment.py", line 1304, in render
    self.environment.handle_exception()
  File "/usr/local/lib/python3.8/site-packages/jinja2/environment.py", line 939, in handle_exception
    raise rewrite_traceback_stack(source=source)
  File "/app/app/templates/view_user_details.html", line 98, in top-level template code
    <a href="{{ url_for('withdraw', encrypted_account_number=encrypt(user.account_number)) }}" class="button"><i class="fas fa-money-bill-wave"></i> Withdraw</a>
  File "/usr/local/lib/python3.8/site-packages/jinja2/utils.py", line 83, in from_obj
    if hasattr(obj, "jinja_pass_arg"):
jinja2.exceptions.UndefinedError: 'encrypt' is undefined
2024-08-31 08:21:47,284 - ERROR - Exception on /view_user_details/gAAAAABm0tKZlruBSmIfwRKHFMC7WpTmP12I0Cqvo0jIrU-guC1ZqMzL7wke_1KbP7I95K1N7qqVmoOimSfBm-IyPop-Jnjtew== [GET]
Traceback (most recent call last):
  File "/usr/local/lib/python3.8/site-packages/flask/app.py", line 1473, in wsgi_app
    response = self.full_dispatch_request()
  File "/usr/local/lib/python3.8/site-packages/flask/app.py", line 882, in full_dispatch_request
    rv = self.handle_user_exception(e)
  File "/usr/local/lib/python3.8/site-packages/flask/app.py", line 880, in full_dispatch_request
    rv = self.dispatch_request()
  File "/usr/local/lib/python3.8/site-packages/flask/app.py", line 865, in dispatch_request
    return self.ensure_sync(self.view_functions[rule.endpoint])(**view_args)  # type: ignore[no-any-return]
  File "/app/app/views.py", line 40, in decorated_function
    return f(*args, **kwargs)
  File "/app/app/views.py", line 142, in view_user_details
    return render_template('view_user_details.html', user=user, account=account)
  File "/usr/local/lib/python3.8/site-packages/flask/templating.py", line 150, in render_template
    return _render(app, template, context)
  File "/usr/local/lib/python3.8/site-packages/flask/templating.py", line 131, in _render
    rv = template.render(context)
  File "/usr/local/lib/python3.8/site-packages/jinja2/environment.py", line 1304, in render
    self.environment.handle_exception()
  File "/usr/local/lib/python3.8/site-packages/jinja2/environment.py", line 939, in handle_exception
    raise rewrite_traceback_stack(source=source)
  File "/app/app/templates/view_user_details.html", line 98, in top-level template code
    <a href="{{ url_for('withdraw', encrypted_account_number=encrypt(user.account_number)) }}" class="button"><i class="fas fa-money-bill-wave"></i> Withdraw</a>
  File "/usr/local/lib/python3.8/site-packages/jinja2/utils.py", line 83, in from_obj
    if hasattr(obj, "jinja_pass_arg"):
jinja2.exceptions.UndefinedError: 'encrypt' is undefined
2024-08-31 08:29:08,094 - ERROR - Exception on /withdraw/gAAAAABm0tRSHpvRJaZJY9te0xUU-0mKtvES7TfT1Y7_zdEKYQOapshorSjsne95W1uA7524dRaNb4vjc-xBzBkyD1JPb--v_A== [GET]
Traceback (most recent call last):
  File "/usr/local/lib/python3.8/site-packages/flask/app.py", line 1473, in wsgi_app
    response = self.full_dispatch_request()
  File "/usr/local/lib/python3.8/site-packages/flask/app.py", line 882, in full_dispatch_request
    rv = self.handle_user_exception(e)
  File "/usr/local/lib/python3.8/site-packages/flask/app.py", line 880, in full_dispatch_request
    rv = self.dispatch_request()
  File "/usr/local/lib/python3.8/site-packages/flask/app.py", line 865, in dispatch_request
    return self.ensure_sync(self.view_functions[rule.endpoint])(**view_args)  # type: ignore[no-any-return]
  File "/app/app/withdraw.py", line 26, in withdraw
    account_number = decrypt_account_number(encrypted_account_number)
NameError: name 'decrypt_account_number' is not defined
2024-08-31 08:30:07,389 - ERROR - Exception on /withdraw/gAAAAABm0tRSHpvRJaZJY9te0xUU-0mKtvES7TfT1Y7_zdEKYQOapshorSjsne95W1uA7524dRaNb4vjc-xBzBkyD1JPb--v_A== [GET]
Traceback (most recent call last):
  File "/usr/local/lib/python3.8/site-packages/flask/app.py", line 1473, in wsgi_app
    response = self.full_dispatch_request()
  File "/usr/local/lib/python3.8/site-packages/flask/app.py", line 882, in full_dispatch_request
    rv = self.handle_user_exception(e)
  File "/usr/local/lib/python3.8/site-packages/flask/app.py", line 880, in full_dispatch_request
    rv = self.dispatch_request()
  File "/usr/local/lib/python3.8/site-packages/flask/app.py", line 865, in dispatch_request
    return self.ensure_sync(self.view_functions[rule.endpoint])(**view_args)  # type: ignore[no-any-return]
  File "/app/app/withdraw.py", line 26, in withdraw
    account_number = decrypt_account_number(encrypted_account_number)
NameError: name 'decrypt_account_number' is not defined
2024-08-31 08:32:47,596 - ERROR - Exception on /withdraw/gAAAAABm0tUuZFvhq4rzrqTsnR_idDKRv9Q6Pa6ZkpmzPB6i1l_VBiH9Q37Idaa1OZEngGzfWVuFVABbIlF--rdzIdSc9SwB5Q== [GET]
Traceback (most recent call last):
  File "/usr/local/lib/python3.8/site-packages/flask/app.py", line 1473, in wsgi_app
    response = self.full_dispatch_request()
  File "/usr/local/lib/python3.8/site-packages/flask/app.py", line 882, in full_dispatch_request
    rv = self.handle_user_exception(e)
  File "/usr/local/lib/python3.8/site-packages/flask/app.py", line 880, in full_dispatch_request
    rv = self.dispatch_request()
  File "/usr/local/lib/python3.8/site-packages/flask/app.py", line 865, in dispatch_request
    return self.ensure_sync(self.view_functions[rule.endpoint])(**view_args)  # type: ignore[no-any-return]
  File "/app/app/withdraw.py", line 26, in withdraw
    account_number = decrypt(encrypted_account_number)
NameError: name 'decrypt' is not defined
2024-08-31 08:35:17,718 - ERROR - Exception on /withdraw/gAAAAABm0tXEuV3n2GRhuTAObWrRSHHBntv6AlgJV8d1PGvXWfCjHmoZwhnjZoHrhmqaZBlG5nGp1OUBFhT8_6mF02GklX_Zmg== [GET]
Traceback (most recent call last):
  File "/usr/local/lib/python3.8/site-packages/flask/app.py", line 1473, in wsgi_app
    response = self.full_dispatch_request()
  File "/usr/local/lib/python3.8/site-packages/flask/app.py", line 882, in full_dispatch_request
    rv = self.handle_user_exception(e)
  File "/usr/local/lib/python3.8/site-packages/flask/app.py", line 880, in full_dispatch_request
    rv = self.dispatch_request()
  File "/usr/local/lib/python3.8/site-packages/flask/app.py", line 865, in dispatch_request
    return self.ensure_sync(self.view_functions[rule.endpoint])(**view_args)  # type: ignore[no-any-return]
  File "/app/app/withdraw.py", line 30, in withdraw
    account = Account.query.filter_by(account_number=user.account_number).first()
NameError: name 'user' is not defined
