2024-08-31 07:52:59,153 - ERROR - Exception on /all_users [GET]
Traceback (most recent call last):
  File "/usr/local/lib/python3.8/site-packages/flask/app.py", line 1473, in wsgi_app
    response = self.full_dispatch_request()
  File "/usr/local/lib/python3.8/site-packages/flask/app.py", line 882, in full_dispatch_request
    rv = self.handle_user_exception(e)
  File "/usr/local/lib/python3.8/site-packages/flask/app.py", line 880, in full_dispatch_request
    rv = self.dispatch_request()
  File "/usr/local/lib/python3.8/site-packages/flask/app.py", line 865, in dispatch_request
    return self.ensure_sync(self.view_functions[rule.endpoint])(**view_args)  # type: ignore[no-any-return]
  File "/app/app/views.py", line 41, in decorated_function
    return f(*args, **kwargs)
  File "/app/app/views.py", line 129, in all_users
    return render_template('all_users.html', users=users, encrypt_account_number=encrypt_account_number)
  File "/usr/local/lib/python3.8/site-packages/flask/templating.py", line 150, in render_template
    return _render(app, template, context)
  File "/usr/local/lib/python3.8/site-packages/flask/templating.py", line 131, in _render
    rv = template.render(context)
  File "/usr/local/lib/python3.8/site-packages/jinja2/environment.py", line 1304, in render
    self.environment.handle_exception()
  File "/usr/local/lib/python3.8/site-packages/jinja2/environment.py", line 939, in handle_exception
    raise rewrite_traceback_stack(source=source)
  File "/app/app/templates/all_users.html", line 40, in top-level template code
    <td><a href="{{ url_for('view_user_details', encrypted_account_number=encrypt(user.account_number)) }}" class="button">View Details</a></td> <!-- Link to the edit page -->
  File "/usr/local/lib/python3.8/site-packages/jinja2/utils.py", line 83, in from_obj
    if hasattr(obj, "jinja_pass_arg"):
jinja2.exceptions.UndefinedError: 'encrypt' is undefined
2024-08-31 07:55:15,514 - ERROR - Exception on /all_users [GET]
Traceback (most recent call last):
  File "/usr/local/lib/python3.8/site-packages/flask/app.py", line 1473, in wsgi_app
    response = self.full_dispatch_request()
  File "/usr/local/lib/python3.8/site-packages/flask/app.py", line 882, in full_dispatch_request
    rv = self.handle_user_exception(e)
  File "/usr/local/lib/python3.8/site-packages/flask/app.py", line 880, in full_dispatch_request
    rv = self.dispatch_request()
  File "/usr/local/lib/python3.8/site-packages/flask/app.py", line 865, in dispatch_request
    return self.ensure_sync(self.view_functions[rule.endpoint])(**view_args)  # type: ignore[no-any-return]
  File "/app/app/views.py", line 41, in decorated_function
    return f(*args, **kwargs)
  File "/app/app/views.py", line 129, in all_users
    return render_template('all_users.html', users=users, encrypt=encrypt)
  File "/usr/local/lib/python3.8/site-packages/flask/templating.py", line 150, in render_template
    return _render(app, template, context)
  File "/usr/local/lib/python3.8/site-packages/flask/templating.py", line 131, in _render
    rv = template.render(context)
  File "/usr/local/lib/python3.8/site-packages/jinja2/environment.py", line 1304, in render
    self.environment.handle_exception()
  File "/usr/local/lib/python3.8/site-packages/jinja2/environment.py", line 939, in handle_exception
    raise rewrite_traceback_stack(source=source)
  File "/app/app/templates/all_users.html", line 40, in top-level template code
    <td><a href="{{ url_for('view_user_details', encrypted_account_number=encrypt(user.account_number)) }}" class="button">View Details</a></td> <!-- Link to the edit page -->
  File "/app/app/views.py", line 27, in encrypt
    return cipher_suite.encrypt(account_number.encode()).decode()
AttributeError: 'int' object has no attribute 'encode'
2024-08-31 08:00:19,319 - ERROR - Exception on /all_users [GET]
Traceback (most recent call last):
  File "/usr/local/lib/python3.8/site-packages/flask/app.py", line 1473, in wsgi_app
    response = self.full_dispatch_request()
  File "/usr/local/lib/python3.8/site-packages/flask/app.py", line 882, in full_dispatch_request
    rv = self.handle_user_exception(e)
  File "/usr/local/lib/python3.8/site-packages/flask/app.py", line 880, in full_dispatch_request
    rv = self.dispatch_request()
  File "/usr/local/lib/python3.8/site-packages/flask/app.py", line 865, in dispatch_request
    return self.ensure_sync(self.view_functions[rule.endpoint])(**view_args)  # type: ignore[no-any-return]
  File "/app/app/views.py", line 41, in decorated_function
    return f(*args, **kwargs)
  File "/app/app/views.py", line 129, in all_users
    return render_template('all_users.html', users=users, encrypt=encrypt)
  File "/usr/local/lib/python3.8/site-packages/flask/templating.py", line 150, in render_template
    return _render(app, template, context)
  File "/usr/local/lib/python3.8/site-packages/flask/templating.py", line 131, in _render
    rv = template.render(context)
  File "/usr/local/lib/python3.8/site-packages/jinja2/environment.py", line 1304, in render
    self.environment.handle_exception()
  File "/usr/local/lib/python3.8/site-packages/jinja2/environment.py", line 939, in handle_exception
    raise rewrite_traceback_stack(source=source)
  File "/app/app/templates/all_users.html", line 40, in top-level template code
    <td><a href="{{ url_for('view_user_details', encrypted_account_number=encrypt(user.account_number)) }}" class="button">View Details</a></td> <!-- Link to the edit page -->
  File "/app/app/views.py", line 27, in encrypt
    return cipher_suite.encrypt(account_number.encode()).decode()
AttributeError: 'int' object has no attribute 'encode'
2024-08-31 08:01:24,942 - ERROR - Exception on /all_users [GET]
Traceback (most recent call last):
  File "/usr/local/lib/python3.8/site-packages/flask/app.py", line 1473, in wsgi_app
    response = self.full_dispatch_request()
  File "/usr/local/lib/python3.8/site-packages/flask/app.py", line 882, in full_dispatch_request
    rv = self.handle_user_exception(e)
  File "/usr/local/lib/python3.8/site-packages/flask/app.py", line 880, in full_dispatch_request
    rv = self.dispatch_request()
  File "/usr/local/lib/python3.8/site-packages/flask/app.py", line 865, in dispatch_request
    return self.ensure_sync(self.view_functions[rule.endpoint])(**view_args)  # type: ignore[no-any-return]
  File "/app/app/views.py", line 41, in decorated_function
    return f(*args, **kwargs)
  File "/app/app/views.py", line 129, in all_users
    return render_template('all_users.html', users=users, encrypt=encrypt)
  File "/usr/local/lib/python3.8/site-packages/flask/templating.py", line 150, in render_template
    return _render(app, template, context)
  File "/usr/local/lib/python3.8/site-packages/flask/templating.py", line 131, in _render
    rv = template.render(context)
  File "/usr/local/lib/python3.8/site-packages/jinja2/environment.py", line 1304, in render
    self.environment.handle_exception()
  File "/usr/local/lib/python3.8/site-packages/jinja2/environment.py", line 939, in handle_exception
    raise rewrite_traceback_stack(source=source)
  File "/app/app/templates/all_users.html", line 40, in top-level template code
    <td><a href="{{ url_for('view_user_details', encrypted_account_number=encrypt(user.account_number)) }}" class="button">View Details</a></td> <!-- Link to the edit page -->
  File "/app/app/views.py", line 27, in encrypt
    return cipher_suite.encrypt(str(account_number.encode()).decode())
AttributeError: 'int' object has no attribute 'encode'
2024-08-31 08:03:27,718 - ERROR - Exception on /edit_user/1821014501 [POST]
Traceback (most recent call last):
  File "/usr/local/lib/python3.8/site-packages/flask/app.py", line 1473, in wsgi_app
    response = self.full_dispatch_request()
  File "/usr/local/lib/python3.8/site-packages/flask/app.py", line 882, in full_dispatch_request
    rv = self.handle_user_exception(e)
  File "/usr/local/lib/python3.8/site-packages/flask/app.py", line 880, in full_dispatch_request
    rv = self.dispatch_request()
  File "/usr/local/lib/python3.8/site-packages/flask/app.py", line 865, in dispatch_request
    return self.ensure_sync(self.view_functions[rule.endpoint])(**view_args)  # type: ignore[no-any-return]
  File "/app/app/views.py", line 41, in decorated_function
    return f(*args, **kwargs)
  File "/app/app/views.py", line 185, in edit_user
    return redirect(url_for('view_user_details', account_number=user.account_number))
  File "/usr/local/lib/python3.8/site-packages/flask/helpers.py", line 220, in url_for
    return current_app.url_for(
  File "/usr/local/lib/python3.8/site-packages/flask/app.py", line 1084, in url_for
    return self.handle_url_build_error(error, endpoint, values)
  File "/usr/local/lib/python3.8/site-packages/flask/app.py", line 1073, in url_for
    rv = url_adapter.build(  # type: ignore[union-attr]
  File "/usr/local/lib/python3.8/site-packages/werkzeug/routing/map.py", line 924, in build
    raise BuildError(endpoint, values, method, self)
werkzeug.routing.exceptions.BuildError: Could not build url for endpoint 'view_user_details' with values ['account_number']. Did you forget to specify values ['encrypted_account_number']?
