2024-08-28 05:07:04,536 - ERROR - Exception on /view_user_details/gAAAAABmzrA0T_MR286cdl9QKUMEElzOYFhllY74Se-RLL2ZHa5fuNXHPL672-a7yctcUQmeZkhwvfOrAEGmkowScSBLqpAVNQ== [GET]
Traceback (most recent call last):
  File "/usr/local/lib/python3.8/site-packages/flask/app.py", line 1473, in wsgi_app
    response = self.full_dispatch_request()
  File "/usr/local/lib/python3.8/site-packages/flask/app.py", line 882, in full_dispatch_request
    rv = self.handle_user_exception(e)
  File "/usr/local/lib/python3.8/site-packages/flask/app.py", line 880, in full_dispatch_request
    rv = self.dispatch_request()
  File "/usr/local/lib/python3.8/site-packages/flask/app.py", line 865, in dispatch_request
    return self.ensure_sync(self.view_functions[rule.endpoint])(**view_args)  # type: ignore[no-any-return]
  File "/app/app/views.py", line 42, in decorated_function
    return f(*args, **kwargs)
  File "/app/app/views.py", line 156, in view_user_details
    return render_template('view_user_details.html', user=user, account=account)
  File "/usr/local/lib/python3.8/site-packages/flask/templating.py", line 150, in render_template
    return _render(app, template, context)
  File "/usr/local/lib/python3.8/site-packages/flask/templating.py", line 131, in _render
    rv = template.render(context)
  File "/usr/local/lib/python3.8/site-packages/jinja2/environment.py", line 1304, in render
    self.environment.handle_exception()
  File "/usr/local/lib/python3.8/site-packages/jinja2/environment.py", line 939, in handle_exception
    raise rewrite_traceback_stack(source=source)
  File "/app/app/templates/view_user_details.html", line 98, in top-level template code
    <a href="{{ url_for('withdraw', account_number=user.account_number) }}" class="button"><i class="fas fa-money-bill-wave"></i> Withdraw</a>
  File "/usr/local/lib/python3.8/site-packages/jinja2/utils.py", line 83, in from_obj
    if hasattr(obj, "jinja_pass_arg"):
jinja2.exceptions.UndefinedError: 'encrypt' is undefined
2024-08-28 05:07:05,620 - ERROR - Exception on /view_user_details/gAAAAABmzrA0T_MR286cdl9QKUMEElzOYFhllY74Se-RLL2ZHa5fuNXHPL672-a7yctcUQmeZkhwvfOrAEGmkowScSBLqpAVNQ== [GET]
Traceback (most recent call last):
  File "/usr/local/lib/python3.8/site-packages/flask/app.py", line 1473, in wsgi_app
    response = self.full_dispatch_request()
  File "/usr/local/lib/python3.8/site-packages/flask/app.py", line 882, in full_dispatch_request
    rv = self.handle_user_exception(e)
  File "/usr/local/lib/python3.8/site-packages/flask/app.py", line 880, in full_dispatch_request
    rv = self.dispatch_request()
  File "/usr/local/lib/python3.8/site-packages/flask/app.py", line 865, in dispatch_request
    return self.ensure_sync(self.view_functions[rule.endpoint])(**view_args)  # type: ignore[no-any-return]
  File "/app/app/views.py", line 42, in decorated_function
    return f(*args, **kwargs)
  File "/app/app/views.py", line 156, in view_user_details
    return render_template('view_user_details.html', user=user, account=account)
  File "/usr/local/lib/python3.8/site-packages/flask/templating.py", line 150, in render_template
    return _render(app, template, context)
  File "/usr/local/lib/python3.8/site-packages/flask/templating.py", line 131, in _render
    rv = template.render(context)
  File "/usr/local/lib/python3.8/site-packages/jinja2/environment.py", line 1304, in render
    self.environment.handle_exception()
  File "/usr/local/lib/python3.8/site-packages/jinja2/environment.py", line 939, in handle_exception
    raise rewrite_traceback_stack(source=source)
  File "/app/app/templates/view_user_details.html", line 98, in top-level template code
    <a href="{{ url_for('withdraw', account_number=user.account_number) }}" class="button"><i class="fas fa-money-bill-wave"></i> Withdraw</a>
  File "/usr/local/lib/python3.8/site-packages/jinja2/utils.py", line 83, in from_obj
    if hasattr(obj, "jinja_pass_arg"):
jinja2.exceptions.UndefinedError: 'encrypt' is undefined
2024-08-28 05:07:06,402 - ERROR - Exception on /view_user_details/gAAAAABmzrA0T_MR286cdl9QKUMEElzOYFhllY74Se-RLL2ZHa5fuNXHPL672-a7yctcUQmeZkhwvfOrAEGmkowScSBLqpAVNQ== [GET]
Traceback (most recent call last):
  File "/usr/local/lib/python3.8/site-packages/flask/app.py", line 1473, in wsgi_app
    response = self.full_dispatch_request()
  File "/usr/local/lib/python3.8/site-packages/flask/app.py", line 882, in full_dispatch_request
    rv = self.handle_user_exception(e)
  File "/usr/local/lib/python3.8/site-packages/flask/app.py", line 880, in full_dispatch_request
    rv = self.dispatch_request()
  File "/usr/local/lib/python3.8/site-packages/flask/app.py", line 865, in dispatch_request
    return self.ensure_sync(self.view_functions[rule.endpoint])(**view_args)  # type: ignore[no-any-return]
  File "/app/app/views.py", line 42, in decorated_function
    return f(*args, **kwargs)
  File "/app/app/views.py", line 156, in view_user_details
    return render_template('view_user_details.html', user=user, account=account)
  File "/usr/local/lib/python3.8/site-packages/flask/templating.py", line 150, in render_template
    return _render(app, template, context)
  File "/usr/local/lib/python3.8/site-packages/flask/templating.py", line 131, in _render
    rv = template.render(context)
  File "/usr/local/lib/python3.8/site-packages/jinja2/environment.py", line 1304, in render
    self.environment.handle_exception()
  File "/usr/local/lib/python3.8/site-packages/jinja2/environment.py", line 939, in handle_exception
    raise rewrite_traceback_stack(source=source)
  File "/app/app/templates/view_user_details.html", line 98, in top-level template code
    <a href="{{ url_for('withdraw', account_number=user.account_number) }}" class="button"><i class="fas fa-money-bill-wave"></i> Withdraw</a>
  File "/usr/local/lib/python3.8/site-packages/jinja2/utils.py", line 83, in from_obj
    if hasattr(obj, "jinja_pass_arg"):
jinja2.exceptions.UndefinedError: 'encrypt' is undefined
2024-08-28 05:07:31,617 - ERROR - Exception on /view_user_details/gAAAAABmzrCSc8Frqn_Ysrxn4pzon_4YUINQp4Z1Q7YJ8mp8dgVZGdeyDE7PPEurs3oAMDWP33scXorVeMP9viDU56Nm2U4HxQ== [GET]
Traceback (most recent call last):
  File "/usr/local/lib/python3.8/site-packages/flask/app.py", line 1473, in wsgi_app
    response = self.full_dispatch_request()
  File "/usr/local/lib/python3.8/site-packages/flask/app.py", line 882, in full_dispatch_request
    rv = self.handle_user_exception(e)
  File "/usr/local/lib/python3.8/site-packages/flask/app.py", line 880, in full_dispatch_request
    rv = self.dispatch_request()
  File "/usr/local/lib/python3.8/site-packages/flask/app.py", line 865, in dispatch_request
    return self.ensure_sync(self.view_functions[rule.endpoint])(**view_args)  # type: ignore[no-any-return]
  File "/app/app/views.py", line 42, in decorated_function
    return f(*args, **kwargs)
  File "/app/app/views.py", line 156, in view_user_details
    return render_template('view_user_details.html', user=user, account=account)
  File "/usr/local/lib/python3.8/site-packages/flask/templating.py", line 150, in render_template
    return _render(app, template, context)
  File "/usr/local/lib/python3.8/site-packages/flask/templating.py", line 131, in _render
    rv = template.render(context)
  File "/usr/local/lib/python3.8/site-packages/jinja2/environment.py", line 1304, in render
    self.environment.handle_exception()
  File "/usr/local/lib/python3.8/site-packages/jinja2/environment.py", line 939, in handle_exception
    raise rewrite_traceback_stack(source=source)
  File "/app/app/templates/view_user_details.html", line 98, in top-level template code
    <a href="{{ url_for('withdraw', account_number=user.account_number) }}" class="button"><i class="fas fa-money-bill-wave"></i> Withdraw</a>
  File "/usr/local/lib/python3.8/site-packages/flask/app.py", line 1084, in url_for
    return self.handle_url_build_error(error, endpoint, values)
  File "/usr/local/lib/python3.8/site-packages/flask/app.py", line 1073, in url_for
    rv = url_adapter.build(  # type: ignore[union-attr]
  File "/usr/local/lib/python3.8/site-packages/werkzeug/routing/map.py", line 924, in build
    raise BuildError(endpoint, values, method, self)
werkzeug.routing.exceptions.BuildError: Could not build url for endpoint 'withdraw' with values ['account_number']. Did you forget to specify values ['encrypted_account_number']?
